<robot name="onshape" xmlns:xacro="http://www.ros.org/wiki/xacro">
<link name="body">
<visual>
<origin xyz="-1.3877787807814456755e-17 2.268044627227321576e-18 -0.019999999999999996947" rpy="-1.307114139148519018e-15 -8.6042284408450440465e-16 -1.5707963267948943376" />
<geometry>
<mesh filename="package://my_package/description/body.stl"/>
</geometry>
<material name="body_material">
<color rgba="0.61568627450980395466 0.81176470588235294379 0.92941176470588238168 1.0"/>
</material>
</visual>
<collision>
<origin xyz="-1.3877787807814456755e-17 2.268044627227321576e-18 -0.019999999999999996947" rpy="-1.307114139148519018e-15 -8.6042284408450440465e-16 -1.5707963267948943376" />
<geometry>
<mesh filename="package://my_package/description/body.stl"/>
</geometry>
</collision>
<inertial>
<origin xyz="-2.1197314861468266682e-17 -3.047091972925169955e-18 -0.0099999999999999568401" rpy="0 0 0"/>
<mass value="0.27501886641472944595" />
<inertia ixx="0.00013588878231084587536" ixy="-1.9478911643668652483e-18"  ixz="-1.3217713434262067315e-18" iyy="0.00075777043457423689729" iyz="-1.4051522964996200781e-18" izz="0.00087532462579078835346" />
</inertial>
</link>

<link name="coxa">
<visual>
<origin xyz="-3.4694469519536141888e-18 1.3877787807814456755e-17 0.010000000000000000208" rpy="3.141592653589793116 5.5004085796292419409e-32 4.5556233138191881837e-18" />
<geometry>
<mesh filename="package://my_package/description/coxa.stl"/>
</geometry>
<material name="coxa_material">
<color rgba="0.61568627450980395466 0.81176470588235294379 0.92941176470588238168 1.0"/>
</material>
</visual>
<collision>
<origin xyz="-3.4694469519536141888e-18 1.3877787807814456755e-17 0.010000000000000000208" rpy="3.141592653589793116 5.5004085796292419409e-32 4.5556233138191881837e-18" />
<geometry>
<mesh filename="package://my_package/description/coxa.stl"/>
</geometry>
</collision>
<inertial>
<origin xyz="-0.0098878038941457545297 1.454624625595790109e-17 -1.7347234759768070944e-18" rpy="0 0 0"/>
<mass value="0.0066122388678941162662" />
<inertia ixx="6.8894459355149527586e-07" ixy="8.6607033057752549101e-23"  ixz="-1.7225448468792264995e-37" iyy="1.2166590501427852292e-06" iyz="-7.5309873030771456613e-38" izz="6.3103311382374083454e-07" />
</inertial>
</link>

<link name="femur">
<visual>
<origin xyz="0 0 0.010000000000000008882" rpy="1.570796326794896558 1.5223094932780180466e-17 -7.8923515034929140185e-32" />
<geometry>
<mesh filename="package://my_package/description/femur.stl"/>
</geometry>
<material name="femur_material">
<color rgba="0.61568627450980395466 0.81176470588235294379 0.92941176470588238168 1.0"/>
</material>
</visual>
<collision>
<origin xyz="0 0 0.010000000000000008882" rpy="1.570796326794896558 1.5223094932780180466e-17 -7.8923515034929140185e-32" />
<geometry>
<mesh filename="package://my_package/description/femur.stl"/>
</geometry>
</collision>
<inertial>
<origin xyz="-0.026510642456918004362 1.8402179600664836626e-18 5.6077444547810766431e-18" rpy="0 0 0"/>
<mass value="0.013450238867894117462" />
<inertia ixx="2.1649254300340443086e-06" ixy="-5.5945827232314155516e-36"  ixz="-1.3547820864336366081e-23" iyy="9.0512478346558164569e-06" iyz="4.7613665983016728597e-37" izz="7.3700503904704495049e-06" />
</inertial>
</link>

<link name="tibia">
<visual>
<origin xyz="0 1.7347234759768070944e-18 -0.015000000000000013323" rpy="-1.570796326794896558 1.3517460133816831328e-17 -8.5081885466447089729e-31" />
<geometry>
<mesh filename="package://my_package/description/tibia.stl"/>
</geometry>
<material name="tibia_material">
<color rgba="0.61568627450980395466 0.81176470588235294379 0.92941176470588238168 1.0"/>
</material>
</visual>
<collision>
<origin xyz="0 1.7347234759768070944e-18 -0.015000000000000013323" rpy="-1.570796326794896558 1.3517460133816831328e-17 -8.5081885466447089729e-31" />
<geometry>
<mesh filename="package://my_package/description/tibia.stl"/>
</geometry>
</collision>
<inertial>
<origin xyz="-0.053082265130081331128 1.5811221729689358562e-18 -0.015000000000000008119" rpy="0 0 0"/>
<mass value="0.022426947953717843443" />
<inertia ixx="1.735164583888396196e-06" ixy="6.3288717590687778562e-37"  ixz="-3.3412335132783284521e-22" iyy="3.4042410034078329512e-05" iyz="-8.2982180307905040108e-36" izz="3.3106944055059642142e-05" />
</inertial>
</link>

<joint name="leg1_tibia" type="revolute">
<origin xyz="-0.065000000000000016098 0 -0.014999999999999999445" rpy="3.1415926535897917837 9.3760722639668984015e-16 2.9789574918205247681e-15" />
<parent link="femur" />
<child link="tibia" />
<axis xyz="0 0 1"/>
<limit effort="1" velocity="20" lower="-1.570796326794896558" upper="1.570796326794896558"/>
<joint_properties friction="0.0"/>
</joint>

<joint name="leg1_femur" type="revolute">
<origin xyz="-0.018750000000000002776 2.7755575615628913511e-17 1.7347234759768070944e-18" rpy="-1.570796326794896558 3.7256337959315223206e-15 6.8977934822781091824e-16" />
<parent link="coxa" />
<child link="femur" />
<axis xyz="0 0 1"/>
<limit effort="1" velocity="20" lower="-1.570796326794896558" upper="1.570796326794896558"/>
<joint_properties friction="0.0"/>
</joint>

<joint name="leg1_coxa" type="revolute">
<origin xyz="-0.069999999999999784617 -0.034999999999999517608 -0.009999999999999913472" rpy="3.141592653589793116 -2.6131917083583912597e-16 2.0093044270380251426" />
<parent link="body" />
<child link="coxa" />
<axis xyz="0 0 1"/>
<limit effort="1" velocity="20" lower="-0.69813170079773179122" upper="0.69813170079773179122"/>
<joint_properties friction="0.0"/>
</joint>

<link name="coxa_2">
<visual>
<origin xyz="-6.9388939039072283776e-18 -1.7347234759768070944e-18 0.010000000000000000208" rpy="3.141592653589793116 4.8687508994109322365e-31 -3.639664285226391226e-17" />
<geometry>
<mesh filename="package://my_package/description/coxa.stl"/>
</geometry>
<material name="coxa_material">
<color rgba="0.61568627450980395466 0.81176470588235294379 0.92941176470588238168 1.0"/>
</material>
</visual>
<collision>
<origin xyz="-6.9388939039072283776e-18 -1.7347234759768070944e-18 0.010000000000000000208" rpy="3.141592653589793116 4.8687508994109322365e-31 -3.639664285226391226e-17" />
<geometry>
<mesh filename="package://my_package/description/coxa.stl"/>
</geometry>
</collision>
<inertial>
<origin xyz="-0.0098878038941457562644 -6.6133705096227265313e-19 -1.7347234759768070944e-18" rpy="0 0 0"/>
<mass value="0.0066122388678941162662" />
<inertia ixx="6.8894459355149527586e-07" ixy="1.7379348804911974826e-23"  ixz="-2.873855318447587612e-37" iyy="1.2166590501427852292e-06" iyz="-6.9957821077561249786e-37" izz="6.3103311382374083454e-07" />
</inertial>
</link>

<link name="femur_2">
<visual>
<origin xyz="0 -8.6736173798840354721e-19 0.0099999999999999967387" rpy="1.570796326794896558 -1.4667432264526637353e-17 1.3359199716125357734e-17" />
<geometry>
<mesh filename="package://my_package/description/femur.stl"/>
</geometry>
<material name="femur_material">
<color rgba="0.61568627450980395466 0.81176470588235294379 0.92941176470588238168 1.0"/>
</material>
</visual>
<collision>
<origin xyz="0 -8.6736173798840354721e-19 0.0099999999999999967387" rpy="1.570796326794896558 -1.4667432264526637353e-17 1.3359199716125357734e-17" />
<geometry>
<mesh filename="package://my_package/description/femur.stl"/>
</geometry>
</collision>
<inertial>
<origin xyz="-0.026510642456918004362 6.2277656297667714894e-19 -5.5930134804563498753e-18" rpy="0 0 0"/>
<mass value="0.013450238867894117462" />
<inertia ixx="2.1649254300340443086e-06" ixy="2.6371187827759078183e-22"  ixz="4.8924802101504722485e-22" iyy="9.0512478346558198451e-06" iyz="-2.4480733823690736322e-23" izz="7.3700503904704478108e-06" />
</inertial>
</link>

<link name="tibia_2">
<visual>
<origin xyz="1.3877787807814456755e-17 -8.6736173798840354721e-19 -0.014999999999999995975" rpy="-1.570796326794896558 4.3622113214996346543e-18 4.8411895197081064293e-18" />
<geometry>
<mesh filename="package://my_package/description/tibia.stl"/>
</geometry>
<material name="tibia_material">
<color rgba="0.61568627450980395466 0.81176470588235294379 0.92941176470588238168 1.0"/>
</material>
</visual>
<collision>
<origin xyz="1.3877787807814456755e-17 -8.6736173798840354721e-19 -0.014999999999999995975" rpy="-1.570796326794896558 4.3622113214996346543e-18 4.8411895197081064293e-18" />
<geometry>
<mesh filename="package://my_package/description/tibia.stl"/>
</geometry>
</collision>
<inertial>
<origin xyz="-0.053082265130081310311 -1.2779443466264368692e-18 -0.014999999999999990771" rpy="0 0 0"/>
<mass value="0.022426947953717843443" />
<inertia ixx="1.7351645838883957725e-06" ixy="-1.4971553746331119307e-22"  ixz="1.2464034009436725237e-21" iyy="3.404241003407831596e-05" iyz="-9.3187826781925249662e-23" izz="3.3106944055059642142e-05" />
</inertial>
</link>

<joint name="leg2_tibia" type="revolute">
<origin xyz="-0.06500000000000000222 1.4745149545802860303e-17 -0.014999999999999936995" rpy="3.1415926535897886751 -5.4847958313910681146e-15 1.722373055499762378e-15" />
<parent link="femur_2" />
<child link="tibia_2" />
<axis xyz="0 0 1"/>
<limit effort="1" velocity="20" lower="-1.570796326794896558" upper="1.570796326794896558"/>
<joint_properties friction="0.0"/>
</joint>

<joint name="leg2_femur" type="revolute">
<origin xyz="-0.018749999999999981959 -2.9490299091605720605e-17 -6.9388939039072283776e-18" rpy="-1.5707963267948970021 0.10263938107569256508 5.9077974827602372581e-16" />
<parent link="coxa_2" />
<child link="femur_2" />
<axis xyz="0 0 1"/>
<limit effort="1" velocity="20" lower="-1.570796326794896558" upper="1.570796326794896558"/>
<joint_properties friction="0.0"/>
</joint>

<joint name="leg2_coxa" type="revolute">
<origin xyz="1.482474140647206707e-17 -0.034999999999999649447 -0.01000000000000001929" rpy="3.1415926535897891192 -1.1241008124329700111e-15 1.9533464635925961161" />
<parent link="body" />
<child link="coxa_2" />
<axis xyz="0 0 1"/>
<limit effort="1" velocity="20" lower="-0.69813170079773179122" upper="0.69813170079773179122"/>
<joint_properties friction="0.0"/>
</joint>

<link name="coxa_3">
<visual>
<origin xyz="-1.3877787807814456755e-17 6.9388939039072283776e-18 0.010000000000000000208" rpy="-3.141592653589793116 -7.8886090522101180541e-31 -1.9269488880850684396e-17" />
<geometry>
<mesh filename="package://my_package/description/coxa.stl"/>
</geometry>
<material name="coxa_material">
<color rgba="0.61568627450980395466 0.81176470588235294379 0.92941176470588238168 1.0"/>
</material>
</visual>
<collision>
<origin xyz="-1.3877787807814456755e-17 6.9388939039072283776e-18 0.010000000000000000208" rpy="-3.141592653589793116 -7.8886090522101180541e-31 -1.9269488880850684396e-17" />
<geometry>
<mesh filename="package://my_package/description/coxa.stl"/>
</geometry>
</collision>
<inertial>
<origin xyz="-0.009887803894145764938 7.842930389187591427e-18 -1.7347234759768070944e-18" rpy="0 0 0"/>
<mass value="0.0066122388678941162662" />
<inertia ixx="6.8894459355149527586e-07" ixy="6.3232310547136542137e-23"  ixz="5.7542245082054434624e-37" iyy="1.2166590501427852292e-06" iyz="9.3779127845962244074e-37" izz="6.3103311382374083454e-07" />
</inertial>
</link>

<link name="femur_3">
<visual>
<origin xyz="0 0 0.010000000000000001943" rpy="1.570796326794896558 -5.6374949935941447518e-18 1.7095757977547607372e-18" />
<geometry>
<mesh filename="package://my_package/description/femur.stl"/>
</geometry>
<material name="femur_material">
<color rgba="0.61568627450980395466 0.81176470588235294379 0.92941176470588238168 1.0"/>
</material>
</visual>
<collision>
<origin xyz="0 0 0.010000000000000001943" rpy="1.570796326794896558 -5.6374949935941447518e-18 1.7095757977547607372e-18" />
<geometry>
<mesh filename="package://my_package/description/femur.stl"/>
</geometry>
</collision>
<inertial>
<origin xyz="-0.026510642456918004362 1.8136854322349823785e-18 -1.4945361412783962168e-19" rpy="0 0 0"/>
<mass value="0.013450238867894117462" />
<inertia ixx="2.1649254300340443086e-06" ixy="7.5293169882045312391e-23"  ixz="2.4658982810186984124e-22" iyy="9.0512478346558164569e-06" iyz="-3.9716049351751429092e-23" izz="7.3700503904704478108e-06" />
</inertial>
</link>

<link name="tibia_3">
<visual>
<origin xyz="2.7755575615628913511e-17 8.6736173798840354721e-19 -0.014999999999999992506" rpy="-1.570796326794896558 3.3087598135028085938e-17 5.4667535885344260381e-18" />
<geometry>
<mesh filename="package://my_package/description/tibia.stl"/>
</geometry>
<material name="tibia_material">
<color rgba="0.61568627450980395466 0.81176470588235294379 0.92941176470588238168 1.0"/>
</material>
</visual>
<collision>
<origin xyz="2.7755575615628913511e-17 8.6736173798840354721e-19 -0.014999999999999992506" rpy="-1.570796326794896558 3.3087598135028085938e-17 5.4667535885344260381e-18" />
<geometry>
<mesh filename="package://my_package/description/tibia.stl"/>
</geometry>
</collision>
<inertial>
<origin xyz="-0.053082265130081296434 4.2357277159307935299e-19 -0.014999999999999985567" rpy="0 0 0"/>
<mass value="0.022426947953717843443" />
<inertia ixx="1.735164583888396196e-06" ixy="2.2985991172273863315e-22"  ixz="-7.6245897722280647673e-22" iyy="3.4042410034078329512e-05" iyz="4.3542859652763646696e-22" izz="3.3106944055059655695e-05" />
</inertial>
</link>

<joint name="leg3_tibia" type="revolute">
<origin xyz="-0.065000000000000029976 -5.6378512969246230568e-18 -0.015000000000000013323" rpy="-3.1415926535897895633 -1.1722512048908810591e-15 -0.0015212288132572366305" />
<parent link="femur_3" />
<child link="tibia_3" />
<axis xyz="0 0 1"/>
<limit effort="1" velocity="20" lower="-1.570796326794896558" upper="1.570796326794896558"/>
<joint_properties friction="0.0"/>
</joint>

<joint name="leg3_femur" type="revolute">
<origin xyz="-0.018749999999999988898 -6.9388939039072283776e-18 -6.9388939039072283776e-18" rpy="-1.570796326794896558 0.10263938107564378466 1.9295796682733536253e-15" />
<parent link="coxa_3" />
<child link="femur_3" />
<axis xyz="0 0 1"/>
<limit effort="1" velocity="20" lower="-1.570796326794896558" upper="1.570796326794896558"/>
<joint_properties friction="0.0"/>
</joint>

<joint name="leg3_coxa" type="revolute">
<origin xyz="0.070000000000000103806 -0.034999999999999954758 -0.010000000000000100822" rpy="3.1415926535897917837 -4.0856207306205508252e-14 1.9533464635925228414" />
<parent link="body" />
<child link="coxa_3" />
<axis xyz="0 0 1"/>
<limit effort="1" velocity="20" lower="-0.69813170079773179122" upper="0.69813170079773179122"/>
<joint_properties friction="0.0"/>
</joint>

<link name="coxa_4">
<visual>
<origin xyz="2.6020852139652106416e-18 0 0.010000000000000001943" rpy="-3.141592653589793116 8.6281661508548166217e-32 3.7748482115805873446e-17" />
<geometry>
<mesh filename="package://my_package/description/coxa.stl"/>
</geometry>
<material name="coxa_material">
<color rgba="0.61568627450980395466 0.81176470588235294379 0.92941176470588238168 1.0"/>
</material>
</visual>
<collision>
<origin xyz="2.6020852139652106416e-18 0 0.010000000000000001943" rpy="-3.141592653589793116 8.6281661508548166217e-32 3.7748482115805873446e-17" />
<geometry>
<mesh filename="package://my_package/description/coxa.stl"/>
</geometry>
</collision>
<inertial>
<origin xyz="-0.0098878038941457475908 3.4025396962332922459e-19 0" rpy="0 0 0"/>
<mass value="0.0066122388678941162662" />
<inertia ixx="6.8894459355149527586e-07" ixy="-1.9673490296010616888e-23"  ixz="3.4464460013176129743e-38" iyy="1.2166590501427852292e-06" iyz="6.339604418930336833e-38" izz="6.3103311382374083454e-07" />
</inertial>
</link>

<link name="femur_4">
<visual>
<origin xyz="6.9388939039072283776e-18 0 0.009999999999999995004" rpy="1.570796326794896558 5.1695813254985340977e-17 -1.2998147655737614129e-17" />
<geometry>
<mesh filename="package://my_package/description/femur.stl"/>
</geometry>
<material name="femur_material">
<color rgba="0.61568627450980395466 0.81176470588235294379 0.92941176470588238168 1.0"/>
</material>
</visual>
<collision>
<origin xyz="6.9388939039072283776e-18 0 0.009999999999999995004" rpy="1.570796326794896558 5.1695813254985340977e-17 -1.2998147655737614129e-17" />
<geometry>
<mesh filename="package://my_package/description/femur.stl"/>
</geometry>
</collision>
<inertial>
<origin xyz="-0.026510642456917993953 2.1817693045250829718e-18 -7.303128158161517291e-18" rpy="0 0 0"/>
<mass value="0.013450238867894117462" />
<inertia ixx="2.1649254300340434616e-06" ixy="-2.3042961718617378607e-22"  ixz="-8.2975998822470695822e-22" iyy="9.0512478346558198451e-06" iyz="5.1652829520425747092e-23" izz="7.3700503904704495049e-06" />
</inertial>
</link>

<link name="tibia_4">
<visual>
<origin xyz="0 -1.7347234759768070944e-18 -0.015000000000000013323" rpy="-1.570796326794896558 4.4001450285668077396e-17 1.1317693944896376452e-17" />
<geometry>
<mesh filename="package://my_package/description/tibia.stl"/>
</geometry>
<material name="tibia_material">
<color rgba="0.61568627450980395466 0.81176470588235294379 0.92941176470588238168 1.0"/>
</material>
</visual>
<collision>
<origin xyz="0 -1.7347234759768070944e-18 -0.015000000000000013323" rpy="-1.570796326794896558 4.4001450285668077396e-17 1.1317693944896376452e-17" />
<geometry>
<mesh filename="package://my_package/description/tibia.stl"/>
</geometry>
</collision>
<inertial>
<origin xyz="-0.053082265130081331128 -2.4890936096288295016e-18 -0.015000000000000004649" rpy="0 0 0"/>
<mass value="0.022426947953717843443" />
<inertia ixx="1.735164583888396196e-06" ixy="2.7958380732838108358e-22"  ixz="2.5637973726832541977e-22" iyy="3.4042410034078329512e-05" iyz="-1.2904155574756643113e-22" izz="3.3106944055059655695e-05" />
</inertial>
</link>

<joint name="leg4_tibia" type="revolute">
<origin xyz="-0.064999999999999946709 -1.7347234759768070944e-18 -0.014999999999999985567" rpy="3.1415926535897775729 -5.8807709902223642355e-15 -2.5794431640019188493e-14" />
<parent link="femur_4" />
<child link="tibia_4" />
<axis xyz="0 0 1"/>
<limit effort="1" velocity="20" lower="-1.570796326794896558" upper="1.570796326794896558"/>
<joint_properties friction="0.0"/>
</joint>

<joint name="leg4_femur" type="revolute">
<origin xyz="-0.018750000000000006245 1.3877787807814456755e-17 6.9388939039072283776e-18" rpy="-1.570796326794896558 -0.10263938107565613589 -2.5455220956009814657e-15" />
<parent link="coxa_4" />
<child link="femur_4" />
<axis xyz="0 0 1"/>
<limit effort="1" velocity="20" lower="-1.570796326794896558" upper="1.570796326794896558"/>
<joint_properties friction="0.0"/>
</joint>

<joint name="leg4_coxa" type="revolute">
<origin xyz="0.070000000000000103806 0.034999999999999358014 -0.010000000000000161537" rpy="-3.1415926535897917837 4.1633363423443266728e-16 -1.1882461899972029951" />
<parent link="body" />
<child link="coxa_4" />
<axis xyz="0 0 1"/>
<limit effort="1" velocity="20" lower="-0.69813170079773179122" upper="0.69813170079773179122"/>
<joint_properties friction="0.0"/>
</joint>

<link name="coxa_5">
<visual>
<origin xyz="6.9388939039072283776e-18 0 0.010000000000000000208" rpy="3.141592653589793116 1.232595164407830946e-32 -4.251001920100842802e-17" />
<geometry>
<mesh filename="package://my_package/description/coxa.stl"/>
</geometry>
<material name="coxa_material">
<color rgba="0.61568627450980395466 0.81176470588235294379 0.92941176470588238168 1.0"/>
</material>
</visual>
<collision>
<origin xyz="6.9388939039072283776e-18 0 0.010000000000000000208" rpy="3.141592653589793116 1.232595164407830946e-32 -4.251001920100842802e-17" />
<geometry>
<mesh filename="package://my_package/description/coxa.stl"/>
</geometry>
</collision>
<inertial>
<origin xyz="-0.0098878038941457441213 1.1338342914820297231e-18 -1.7347234759768070944e-18" rpy="0 0 0"/>
<mass value="0.0066122388678941162662" />
<inertia ixx="6.8894459355149527586e-07" ixy="-5.4545569108699213042e-23"  ixz="3.6865818004565773115e-38" iyy="1.2166590501427852292e-06" iyz="-1.0763200495592754163e-37" izz="6.3103311382374083454e-07" />
</inertial>
</link>

<link name="femur_5">
<visual>
<origin xyz="-6.9388939039072283776e-18 0 0.010000000000000000208" rpy="1.570796326794896558 -2.3544599737209709738e-17 9.5606514121246145973e-18" />
<geometry>
<mesh filename="package://my_package/description/femur.stl"/>
</geometry>
<material name="femur_material">
<color rgba="0.61568627450980395466 0.81176470588235294379 0.92941176470588238168 1.0"/>
</material>
</visual>
<collision>
<origin xyz="-6.9388939039072283776e-18 0 0.010000000000000000208" rpy="1.570796326794896558 -2.3544599737209709738e-17 9.5606514121246145973e-18" />
<geometry>
<mesh filename="package://my_package/description/femur.stl"/>
</geometry>
</collision>
<inertial>
<origin xyz="-0.0265106424569180113 1.6804036095027205246e-18 -4.0936294173780265563e-18" rpy="0 0 0"/>
<mass value="0.013450238867894117462" />
<inertia ixx="2.1649254300340443086e-06" ixy="-8.390884525065746423e-23"  ixz="3.984242005013794367e-22" iyy="9.0512478346558164569e-06" iyz="-3.2927426989275106847e-23" izz="7.3700503904704495049e-06" />
</inertial>
</link>

<link name="tibia_5">
<visual>
<origin xyz="0 0 -0.01499999999999999771" rpy="-1.570796326794896558 -5.2774159954133786005e-17 1.0824835729230472819e-17" />
<geometry>
<mesh filename="package://my_package/description/tibia.stl"/>
</geometry>
<material name="tibia_material">
<color rgba="0.61568627450980395466 0.81176470588235294379 0.92941176470588238168 1.0"/>
</material>
</visual>
<collision>
<origin xyz="0 0 -0.01499999999999999771" rpy="-1.570796326794896558 -5.2774159954133786005e-17 1.0824835729230472819e-17" />
<geometry>
<mesh filename="package://my_package/description/tibia.stl"/>
</geometry>
</collision>
<inertial>
<origin xyz="-0.053082265130081331128 -7.2820810317650556934e-19 -0.014999999999999995975" rpy="0 0 0"/>
<mass value="0.022426947953717843443" />
<inertia ixx="1.735164583888396196e-06" ixy="6.7844539937225303164e-23"  ixz="3.5650119370144020466e-22" iyy="3.4042410034078343065e-05" iyz="-3.3782595994581203638e-22" izz="3.3106944055059655695e-05" />
</inertial>
</link>

<joint name="leg5_tibia" type="revolute">
<origin xyz="-0.065000000000000016098 1.7347234759768070944e-18 -0.015000000000000021996" rpy="3.1415926535897900074 1.1901845005248213536e-14 3.179248902486337265e-15" />
<parent link="femur_5" />
<child link="tibia_5" />
<axis xyz="0 0 1"/>
<limit effort="1" velocity="20" lower="-1.570796326794896558" upper="1.570796326794896558"/>
<joint_properties friction="0.0"/>
</joint>

<joint name="leg5_femur" type="revolute">
<origin xyz="-0.018749999999999988898 1.9081958235744878039e-17 -1.7347234759768070944e-18" rpy="-1.570796326794896558 -0.10263938107565208357 7.9744037973441187927e-15" />
<parent link="coxa_5" />
<child link="femur_5" />
<axis xyz="0 0 1"/>
<limit effort="1" velocity="20" lower="-1.570796326794896558" upper="1.570796326794896558"/>
<joint_properties friction="0.0"/>
</joint>

<joint name="leg5_coxa" type="revolute">
<origin xyz="4.4082518212383967536e-19 0.034999999999999670264 -0.010000000000000067862" rpy="-3.1415926535897926719 -2.7755575615628795181e-16 -1.1882461899972149855" />
<parent link="body" />
<child link="coxa_5" />
<axis xyz="0 0 1"/>
<limit effort="1" velocity="20" lower="-0.69813170079773179122" upper="0.69813170079773179122"/>
<joint_properties friction="0.0"/>
</joint>

<link name="coxa_6">
<visual>
<origin xyz="0 -6.9388939039072283776e-18 0.0099999999999999984734" rpy="3.141592653589793116 3.3280069439011435541e-31 -2.7222593249677761974e-17" />
<geometry>
<mesh filename="package://my_package/description/coxa.stl"/>
</geometry>
<material name="coxa_material">
<color rgba="0.61568627450980395466 0.81176470588235294379 0.92941176470588238168 1.0"/>
</material>
</visual>
<collision>
<origin xyz="0 -6.9388939039072283776e-18 0.0099999999999999984734" rpy="3.141592653589793116 3.3280069439011435541e-31 -2.7222593249677761974e-17" />
<geometry>
<mesh filename="package://my_package/description/coxa.stl"/>
</geometry>
</collision>
<inertial>
<origin xyz="-0.0098878038941457510602 -5.9562186822782299569e-18 -3.4694469519536141888e-18" rpy="0 0 0"/>
<mass value="0.0066122388678941162662" />
<inertia ixx="6.8894459355149527586e-07" ixy="6.9275014686222742493e-23"  ixz="-2.3203309357872343139e-37" iyy="1.2166590501427852292e-06" iyz="-2.3129303220781239755e-37" izz="6.3103311382374083454e-07" />
</inertial>
</link>

<link name="femur_6">
<visual>
<origin xyz="-2.7755575615628913511e-17 0 0.009999999999999995004" rpy="1.570796326794896558 -1.4534907487943986483e-17 1.9186329757244802885e-17" />
<geometry>
<mesh filename="package://my_package/description/femur.stl"/>
</geometry>
<material name="femur_material">
<color rgba="0.61568627450980395466 0.81176470588235294379 0.92941176470588238168 1.0"/>
</material>
</visual>
<collision>
<origin xyz="-2.7755575615628913511e-17 0 0.009999999999999995004" rpy="1.570796326794896558 -1.4534907487943986483e-17 1.9186329757244802885e-17" />
<geometry>
<mesh filename="package://my_package/description/femur.stl"/>
</geometry>
</collision>
<inertial>
<origin xyz="-0.026510642456918028648 1.3226461265450701834e-18 -7.3242236394644912731e-18" rpy="0 0 0"/>
<mass value="0.013450238867894117462" />
<inertia ixx="2.1649254300340443086e-06" ixy="5.2711708915783757612e-23"  ixz="-1.5618585919516345087e-23" iyy="9.0512478346558164569e-06" iyz="3.4567376463941591476e-24" izz="7.3700503904704478108e-06" />
</inertial>
</link>

<link name="tibia_6">
<visual>
<origin xyz="0 -3.4694469519536141888e-18 -0.014999999999999985567" rpy="-1.570796326794896558 -3.9861636696917712207e-18 -3.5734310233732106771e-18" />
<geometry>
<mesh filename="package://my_package/description/tibia.stl"/>
</geometry>
<material name="tibia_material">
<color rgba="0.61568627450980395466 0.81176470588235294379 0.92941176470588238168 1.0"/>
</material>
</visual>
<collision>
<origin xyz="0 -3.4694469519536141888e-18 -0.014999999999999985567" rpy="-1.570796326794896558 -3.9861636696917712207e-18 -3.5734310233732106771e-18" />
<geometry>
<mesh filename="package://my_package/description/tibia.stl"/>
</geometry>
</collision>
<inertial>
<origin xyz="-0.053082265130081331128 -3.4333624419547760201e-18 -0.014999999999999982098" rpy="0 0 0"/>
<mass value="0.022426947953717843443" />
<inertia ixx="1.735164583888396196e-06" ixy="-5.4078874541209756295e-23"  ixz="-4.1235051213320483656e-22" iyy="3.4042410034078329512e-05" iyz="-9.633525803823083646e-23" izz="3.3106944055059655695e-05" />
</inertial>
</link>

<joint name="leg6_tibia" type="revolute">
<origin xyz="-0.065000000000000043854 -2.0816681711721685133e-17 -0.015000000000000006384" rpy="3.1415926535897904515 3.4450269367260829318e-15 -2.9053030089261606732e-15" />
<parent link="femur_6" />
<child link="tibia_6" />
<axis xyz="0 0 1"/>
<limit effort="1" velocity="20" lower="-1.570796326794896558" upper="1.570796326794896558"/>
<joint_properties friction="0.0"/>
</joint>

<joint name="leg6_femur" type="revolute">
<origin xyz="-0.018749999999999981959 1.3877787807814456755e-17 -5.2041704279304212832e-18" rpy="-1.570796326794896558 -0.10263938107567500968 2.7466128416921718769e-15" />
<parent link="coxa_6" />
<child link="femur_6" />
<axis xyz="0 0 1"/>
<limit effort="1" velocity="20" lower="-1.570796326794896558" upper="1.570796326794896558"/>
<joint_properties friction="0.0"/>
</joint>

<joint name="leg6_coxa" type="revolute">
<origin xyz="-0.070000000000000103806 0.034999999999999975575 -0.01000000000000008521" rpy="3.1415926535897926719 -1.845745778439316832e-15 -1.1882461899971941133" />
<parent link="body" />
<child link="coxa_6" />
<axis xyz="0 0 1"/>
<limit effort="1" velocity="20" lower="-0.69813170079773179122" upper="0.69813170079773179122"/>
<joint_properties friction="0.0"/>
</joint>


</robot>
